
<?xml version="1.0"?>
<!-- Autogenerated by rubiks_cube.ipynb -->
<sdf version="1.7">
  <model name="rubiks_cube">
    <link name="center"/>

    <link name="box_m1_m1_m1">
      <pose>-0.025 -0.025 -0.025 0 0 0</pose>
      <inertial>
        <mass>0.03</mass>
        <inertia>
          <ixx>0.0003125</ixx>
          <ixy>0.0</ixy>
          <ixz>0.0</ixz>
          <iyy>0.0003125</iyy>
          <iyz>0.0</iyz>
          <izz>0.0003125</izz>
        </inertia>
      </inertial>
      <collision name="collision">
        <geometry>
          <box>
            <size>0.025 0.025 0.025</size>
          </box>
        </geometry>
      </collision>
      <visual name="black">
        <geometry>
          <box>
            <size>0.025 0.025 0.025</size>
          </box>
        </geometry>
        <material>
          <diffuse>0 0 0 1</diffuse>
        </material>
      </visual>
      <visual name="x">
        <pose>-0.0125 0 0 0 0 0</pose>
        <geometry>
          <box>
            <size>0.0002 0.02 0.02</size>
          </box>
        </geometry>
        <material>
          <diffuse>0 0 1 1</diffuse>
        </material>
      </visual>
      <visual name="y">
        <pose>0 -0.0125 0 0 0 0</pose>
        <geometry>
          <box>
            <size>0.02 0.0002 0.02</size>
          </box>
        </geometry>
        <material>
          <diffuse>1 0.5 0 1</diffuse>
        </material>
      </visual>
      <visual name="z">
        <pose>0 0 -0.0125 0 0 0</pose>
        <geometry>
          <box>
            <size>0.02 0.02 0.0002</size>
          </box>
        </geometry>
        <material>
          <diffuse>1 1 0 1</diffuse>
        </material>
      </visual>
    </link>      
    <joint name="ball_m1_m1_m1" type="ball">
        <pose>0.025 0.025 0.025 0 0 0</pose> <!-- in child frame -->
        <parent>center</parent>
        <child>box_m1_m1_m1</child>
        <axis>
            <dynamics><damping>0.1</damping></dynamics>
            <limit><effort>0</effort></limit>
        </axis>
    </joint>

    <link name="box_m1_m1_0">
      <pose>-0.025 -0.025 0.0 0 0 0</pose>
      <inertial>
        <mass>0.03</mass>
        <inertia>
          <ixx>0.0003125</ixx>
          <ixy>0.0</ixy>
          <ixz>0.0</ixz>
          <iyy>0.0003125</iyy>
          <iyz>0.0</iyz>
          <izz>0.0003125</izz>
        </inertia>
      </inertial>
      <collision name="collision">
        <geometry>
          <box>
            <size>0.025 0.025 0.025</size>
          </box>
        </geometry>
      </collision>
      <visual name="black">
        <geometry>
          <box>
            <size>0.025 0.025 0.025</size>
          </box>
        </geometry>
        <material>
          <diffuse>0 0 0 1</diffuse>
        </material>
      </visual>
      <visual name="x">
        <pose>-0.0125 0 0 0 0 0</pose>
        <geometry>
          <box>
            <size>0.0002 0.02 0.02</size>
          </box>
        </geometry>
        <material>
          <diffuse>0 0 1 1</diffuse>
        </material>
      </visual>
      <visual name="y">
        <pose>0 -0.0125 0 0 0 0</pose>
        <geometry>
          <box>
            <size>0.02 0.0002 0.02</size>
          </box>
        </geometry>
        <material>
          <diffuse>1 0.5 0 1</diffuse>
        </material>
      </visual>
      <visual name="z">
        <pose>0 0 0.0 0 0 0</pose>
        <geometry>
          <box>
            <size>0.02 0.02 0.0002</size>
          </box>
        </geometry>
        <material>
          <diffuse>1 1 1 1</diffuse>
        </material>
      </visual>
    </link>      
    <joint name="ball_m1_m1_0" type="ball">
        <pose>0.025 0.025 0.0 0 0 0</pose> <!-- in child frame -->
        <parent>center</parent>
        <child>box_m1_m1_0</child>
        <axis>
            <dynamics><damping>0.1</damping></dynamics>
            <limit><effort>0</effort></limit>
        </axis>
    </joint>

    <link name="box_m1_m1_1">
      <pose>-0.025 -0.025 0.025 0 0 0</pose>
      <inertial>
        <mass>0.03</mass>
        <inertia>
          <ixx>0.0003125</ixx>
          <ixy>0.0</ixy>
          <ixz>0.0</ixz>
          <iyy>0.0003125</iyy>
          <iyz>0.0</iyz>
          <izz>0.0003125</izz>
        </inertia>
      </inertial>
      <collision name="collision">
        <geometry>
          <box>
            <size>0.025 0.025 0.025</size>
          </box>
        </geometry>
      </collision>
      <visual name="black">
        <geometry>
          <box>
            <size>0.025 0.025 0.025</size>
          </box>
        </geometry>
        <material>
          <diffuse>0 0 0 1</diffuse>
        </material>
      </visual>
      <visual name="x">
        <pose>-0.0125 0 0 0 0 0</pose>
        <geometry>
          <box>
            <size>0.0002 0.02 0.02</size>
          </box>
        </geometry>
        <material>
          <diffuse>0 0 1 1</diffuse>
        </material>
      </visual>
      <visual name="y">
        <pose>0 -0.0125 0 0 0 0</pose>
        <geometry>
          <box>
            <size>0.02 0.0002 0.02</size>
          </box>
        </geometry>
        <material>
          <diffuse>1 0.5 0 1</diffuse>
        </material>
      </visual>
      <visual name="z">
        <pose>0 0 0.0125 0 0 0</pose>
        <geometry>
          <box>
            <size>0.02 0.02 0.0002</size>
          </box>
        </geometry>
        <material>
          <diffuse>1 1 1 1</diffuse>
        </material>
      </visual>
    </link>      
    <joint name="ball_m1_m1_1" type="ball">
        <pose>0.025 0.025 -0.025 0 0 0</pose> <!-- in child frame -->
        <parent>center</parent>
        <child>box_m1_m1_1</child>
        <axis>
            <dynamics><damping>0.1</damping></dynamics>
            <limit><effort>0</effort></limit>
        </axis>
    </joint>

    <link name="box_m1_0_m1">
      <pose>-0.025 0.0 -0.025 0 0 0</pose>
      <inertial>
        <mass>0.03</mass>
        <inertia>
          <ixx>0.0003125</ixx>
          <ixy>0.0</ixy>
          <ixz>0.0</ixz>
          <iyy>0.0003125</iyy>
          <iyz>0.0</iyz>
          <izz>0.0003125</izz>
        </inertia>
      </inertial>
      <collision name="collision">
        <geometry>
          <box>
            <size>0.025 0.025 0.025</size>
          </box>
        </geometry>
      </collision>
      <visual name="black">
        <geometry>
          <box>
            <size>0.025 0.025 0.025</size>
          </box>
        </geometry>
        <material>
          <diffuse>0 0 0 1</diffuse>
        </material>
      </visual>
      <visual name="x">
        <pose>-0.0125 0 0 0 0 0</pose>
        <geometry>
          <box>
            <size>0.0002 0.02 0.02</size>
          </box>
        </geometry>
        <material>
          <diffuse>0 0 1 1</diffuse>
        </material>
      </visual>
      <visual name="y">
        <pose>0 0.0 0 0 0 0</pose>
        <geometry>
          <box>
            <size>0.02 0.0002 0.02</size>
          </box>
        </geometry>
        <material>
          <diffuse>1 0 0 1</diffuse>
        </material>
      </visual>
      <visual name="z">
        <pose>0 0 -0.0125 0 0 0</pose>
        <geometry>
          <box>
            <size>0.02 0.02 0.0002</size>
          </box>
        </geometry>
        <material>
          <diffuse>1 1 0 1</diffuse>
        </material>
      </visual>
    </link>      
    <joint name="ball_m1_0_m1" type="ball">
        <pose>0.025 0.0 0.025 0 0 0</pose> <!-- in child frame -->
        <parent>center</parent>
        <child>box_m1_0_m1</child>
        <axis>
            <dynamics><damping>0.1</damping></dynamics>
            <limit><effort>0</effort></limit>
        </axis>
    </joint>

    <link name="box_m1_0_0">
      <pose>-0.025 0.0 0.0 0 0 0</pose>
      <inertial>
        <mass>0.03</mass>
        <inertia>
          <ixx>0.0003125</ixx>
          <ixy>0.0</ixy>
          <ixz>0.0</ixz>
          <iyy>0.0003125</iyy>
          <iyz>0.0</iyz>
          <izz>0.0003125</izz>
        </inertia>
      </inertial>
      <collision name="collision">
        <geometry>
          <box>
            <size>0.025 0.025 0.025</size>
          </box>
        </geometry>
      </collision>
      <visual name="black">
        <geometry>
          <box>
            <size>0.025 0.025 0.025</size>
          </box>
        </geometry>
        <material>
          <diffuse>0 0 0 1</diffuse>
        </material>
      </visual>
      <visual name="x">
        <pose>-0.0125 0 0 0 0 0</pose>
        <geometry>
          <box>
            <size>0.0002 0.02 0.02</size>
          </box>
        </geometry>
        <material>
          <diffuse>0 0 1 1</diffuse>
        </material>
      </visual>
      <visual name="y">
        <pose>0 0.0 0 0 0 0</pose>
        <geometry>
          <box>
            <size>0.02 0.0002 0.02</size>
          </box>
        </geometry>
        <material>
          <diffuse>1 0 0 1</diffuse>
        </material>
      </visual>
      <visual name="z">
        <pose>0 0 0.0 0 0 0</pose>
        <geometry>
          <box>
            <size>0.02 0.02 0.0002</size>
          </box>
        </geometry>
        <material>
          <diffuse>1 1 1 1</diffuse>
        </material>
      </visual>
    </link>      
    <joint name="ball_m1_0_0" type="ball">
        <pose>0.025 0.0 0.0 0 0 0</pose> <!-- in child frame -->
        <parent>center</parent>
        <child>box_m1_0_0</child>
        <axis>
            <dynamics><damping>0.1</damping></dynamics>
            <limit><effort>0</effort></limit>
        </axis>
    </joint>

    <link name="box_m1_0_1">
      <pose>-0.025 0.0 0.025 0 0 0</pose>
      <inertial>
        <mass>0.03</mass>
        <inertia>
          <ixx>0.0003125</ixx>
          <ixy>0.0</ixy>
          <ixz>0.0</ixz>
          <iyy>0.0003125</iyy>
          <iyz>0.0</iyz>
          <izz>0.0003125</izz>
        </inertia>
      </inertial>
      <collision name="collision">
        <geometry>
          <box>
            <size>0.025 0.025 0.025</size>
          </box>
        </geometry>
      </collision>
      <visual name="black">
        <geometry>
          <box>
            <size>0.025 0.025 0.025</size>
          </box>
        </geometry>
        <material>
          <diffuse>0 0 0 1</diffuse>
        </material>
      </visual>
      <visual name="x">
        <pose>-0.0125 0 0 0 0 0</pose>
        <geometry>
          <box>
            <size>0.0002 0.02 0.02</size>
          </box>
        </geometry>
        <material>
          <diffuse>0 0 1 1</diffuse>
        </material>
      </visual>
      <visual name="y">
        <pose>0 0.0 0 0 0 0</pose>
        <geometry>
          <box>
            <size>0.02 0.0002 0.02</size>
          </box>
        </geometry>
        <material>
          <diffuse>1 0 0 1</diffuse>
        </material>
      </visual>
      <visual name="z">
        <pose>0 0 0.0125 0 0 0</pose>
        <geometry>
          <box>
            <size>0.02 0.02 0.0002</size>
          </box>
        </geometry>
        <material>
          <diffuse>1 1 1 1</diffuse>
        </material>
      </visual>
    </link>      
    <joint name="ball_m1_0_1" type="ball">
        <pose>0.025 0.0 -0.025 0 0 0</pose> <!-- in child frame -->
        <parent>center</parent>
        <child>box_m1_0_1</child>
        <axis>
            <dynamics><damping>0.1</damping></dynamics>
            <limit><effort>0</effort></limit>
        </axis>
    </joint>

    <link name="box_m1_1_m1">
      <pose>-0.025 0.025 -0.025 0 0 0</pose>
      <inertial>
        <mass>0.03</mass>
        <inertia>
          <ixx>0.0003125</ixx>
          <ixy>0.0</ixy>
          <ixz>0.0</ixz>
          <iyy>0.0003125</iyy>
          <iyz>0.0</iyz>
          <izz>0.0003125</izz>
        </inertia>
      </inertial>
      <collision name="collision">
        <geometry>
          <box>
            <size>0.025 0.025 0.025</size>
          </box>
        </geometry>
      </collision>
      <visual name="black">
        <geometry>
          <box>
            <size>0.025 0.025 0.025</size>
          </box>
        </geometry>
        <material>
          <diffuse>0 0 0 1</diffuse>
        </material>
      </visual>
      <visual name="x">
        <pose>-0.0125 0 0 0 0 0</pose>
        <geometry>
          <box>
            <size>0.0002 0.02 0.02</size>
          </box>
        </geometry>
        <material>
          <diffuse>0 0 1 1</diffuse>
        </material>
      </visual>
      <visual name="y">
        <pose>0 0.0125 0 0 0 0</pose>
        <geometry>
          <box>
            <size>0.02 0.0002 0.02</size>
          </box>
        </geometry>
        <material>
          <diffuse>1 0 0 1</diffuse>
        </material>
      </visual>
      <visual name="z">
        <pose>0 0 -0.0125 0 0 0</pose>
        <geometry>
          <box>
            <size>0.02 0.02 0.0002</size>
          </box>
        </geometry>
        <material>
          <diffuse>1 1 0 1</diffuse>
        </material>
      </visual>
    </link>      
    <joint name="ball_m1_1_m1" type="ball">
        <pose>0.025 -0.025 0.025 0 0 0</pose> <!-- in child frame -->
        <parent>center</parent>
        <child>box_m1_1_m1</child>
        <axis>
            <dynamics><damping>0.1</damping></dynamics>
            <limit><effort>0</effort></limit>
        </axis>
    </joint>

    <link name="box_m1_1_0">
      <pose>-0.025 0.025 0.0 0 0 0</pose>
      <inertial>
        <mass>0.03</mass>
        <inertia>
          <ixx>0.0003125</ixx>
          <ixy>0.0</ixy>
          <ixz>0.0</ixz>
          <iyy>0.0003125</iyy>
          <iyz>0.0</iyz>
          <izz>0.0003125</izz>
        </inertia>
      </inertial>
      <collision name="collision">
        <geometry>
          <box>
            <size>0.025 0.025 0.025</size>
          </box>
        </geometry>
      </collision>
      <visual name="black">
        <geometry>
          <box>
            <size>0.025 0.025 0.025</size>
          </box>
        </geometry>
        <material>
          <diffuse>0 0 0 1</diffuse>
        </material>
      </visual>
      <visual name="x">
        <pose>-0.0125 0 0 0 0 0</pose>
        <geometry>
          <box>
            <size>0.0002 0.02 0.02</size>
          </box>
        </geometry>
        <material>
          <diffuse>0 0 1 1</diffuse>
        </material>
      </visual>
      <visual name="y">
        <pose>0 0.0125 0 0 0 0</pose>
        <geometry>
          <box>
            <size>0.02 0.0002 0.02</size>
          </box>
        </geometry>
        <material>
          <diffuse>1 0 0 1</diffuse>
        </material>
      </visual>
      <visual name="z">
        <pose>0 0 0.0 0 0 0</pose>
        <geometry>
          <box>
            <size>0.02 0.02 0.0002</size>
          </box>
        </geometry>
        <material>
          <diffuse>1 1 1 1</diffuse>
        </material>
      </visual>
    </link>      
    <joint name="ball_m1_1_0" type="ball">
        <pose>0.025 -0.025 0.0 0 0 0</pose> <!-- in child frame -->
        <parent>center</parent>
        <child>box_m1_1_0</child>
        <axis>
            <dynamics><damping>0.1</damping></dynamics>
            <limit><effort>0</effort></limit>
        </axis>
    </joint>

    <link name="box_m1_1_1">
      <pose>-0.025 0.025 0.025 0 0 0</pose>
      <inertial>
        <mass>0.03</mass>
        <inertia>
          <ixx>0.0003125</ixx>
          <ixy>0.0</ixy>
          <ixz>0.0</ixz>
          <iyy>0.0003125</iyy>
          <iyz>0.0</iyz>
          <izz>0.0003125</izz>
        </inertia>
      </inertial>
      <collision name="collision">
        <geometry>
          <box>
            <size>0.025 0.025 0.025</size>
          </box>
        </geometry>
      </collision>
      <visual name="black">
        <geometry>
          <box>
            <size>0.025 0.025 0.025</size>
          </box>
        </geometry>
        <material>
          <diffuse>0 0 0 1</diffuse>
        </material>
      </visual>
      <visual name="x">
        <pose>-0.0125 0 0 0 0 0</pose>
        <geometry>
          <box>
            <size>0.0002 0.02 0.02</size>
          </box>
        </geometry>
        <material>
          <diffuse>0 0 1 1</diffuse>
        </material>
      </visual>
      <visual name="y">
        <pose>0 0.0125 0 0 0 0</pose>
        <geometry>
          <box>
            <size>0.02 0.0002 0.02</size>
          </box>
        </geometry>
        <material>
          <diffuse>1 0 0 1</diffuse>
        </material>
      </visual>
      <visual name="z">
        <pose>0 0 0.0125 0 0 0</pose>
        <geometry>
          <box>
            <size>0.02 0.02 0.0002</size>
          </box>
        </geometry>
        <material>
          <diffuse>1 1 1 1</diffuse>
        </material>
      </visual>
    </link>      
    <joint name="ball_m1_1_1" type="ball">
        <pose>0.025 -0.025 -0.025 0 0 0</pose> <!-- in child frame -->
        <parent>center</parent>
        <child>box_m1_1_1</child>
        <axis>
            <dynamics><damping>0.1</damping></dynamics>
            <limit><effort>0</effort></limit>
        </axis>
    </joint>

    <link name="box_0_m1_m1">
      <pose>0.0 -0.025 -0.025 0 0 0</pose>
      <inertial>
        <mass>0.03</mass>
        <inertia>
          <ixx>0.0003125</ixx>
          <ixy>0.0</ixy>
          <ixz>0.0</ixz>
          <iyy>0.0003125</iyy>
          <iyz>0.0</iyz>
          <izz>0.0003125</izz>
        </inertia>
      </inertial>
      <collision name="collision">
        <geometry>
          <box>
            <size>0.025 0.025 0.025</size>
          </box>
        </geometry>
      </collision>
      <visual name="black">
        <geometry>
          <box>
            <size>0.025 0.025 0.025</size>
          </box>
        </geometry>
        <material>
          <diffuse>0 0 0 1</diffuse>
        </material>
      </visual>
      <visual name="x">
        <pose>0.0 0 0 0 0 0</pose>
        <geometry>
          <box>
            <size>0.0002 0.02 0.02</size>
          </box>
        </geometry>
        <material>
          <diffuse>0 1 0 1</diffuse>
        </material>
      </visual>
      <visual name="y">
        <pose>0 -0.0125 0 0 0 0</pose>
        <geometry>
          <box>
            <size>0.02 0.0002 0.02</size>
          </box>
        </geometry>
        <material>
          <diffuse>1 0.5 0 1</diffuse>
        </material>
      </visual>
      <visual name="z">
        <pose>0 0 -0.0125 0 0 0</pose>
        <geometry>
          <box>
            <size>0.02 0.02 0.0002</size>
          </box>
        </geometry>
        <material>
          <diffuse>1 1 0 1</diffuse>
        </material>
      </visual>
    </link>      
    <joint name="ball_0_m1_m1" type="ball">
        <pose>0.0 0.025 0.025 0 0 0</pose> <!-- in child frame -->
        <parent>center</parent>
        <child>box_0_m1_m1</child>
        <axis>
            <dynamics><damping>0.1</damping></dynamics>
            <limit><effort>0</effort></limit>
        </axis>
    </joint>

    <link name="box_0_m1_0">
      <pose>0.0 -0.025 0.0 0 0 0</pose>
      <inertial>
        <mass>0.03</mass>
        <inertia>
          <ixx>0.0003125</ixx>
          <ixy>0.0</ixy>
          <ixz>0.0</ixz>
          <iyy>0.0003125</iyy>
          <iyz>0.0</iyz>
          <izz>0.0003125</izz>
        </inertia>
      </inertial>
      <collision name="collision">
        <geometry>
          <box>
            <size>0.025 0.025 0.025</size>
          </box>
        </geometry>
      </collision>
      <visual name="black">
        <geometry>
          <box>
            <size>0.025 0.025 0.025</size>
          </box>
        </geometry>
        <material>
          <diffuse>0 0 0 1</diffuse>
        </material>
      </visual>
      <visual name="x">
        <pose>0.0 0 0 0 0 0</pose>
        <geometry>
          <box>
            <size>0.0002 0.02 0.02</size>
          </box>
        </geometry>
        <material>
          <diffuse>0 1 0 1</diffuse>
        </material>
      </visual>
      <visual name="y">
        <pose>0 -0.0125 0 0 0 0</pose>
        <geometry>
          <box>
            <size>0.02 0.0002 0.02</size>
          </box>
        </geometry>
        <material>
          <diffuse>1 0.5 0 1</diffuse>
        </material>
      </visual>
      <visual name="z">
        <pose>0 0 0.0 0 0 0</pose>
        <geometry>
          <box>
            <size>0.02 0.02 0.0002</size>
          </box>
        </geometry>
        <material>
          <diffuse>1 1 1 1</diffuse>
        </material>
      </visual>
    </link>      
    <joint name="ball_0_m1_0" type="ball">
        <pose>0.0 0.025 0.0 0 0 0</pose> <!-- in child frame -->
        <parent>center</parent>
        <child>box_0_m1_0</child>
        <axis>
            <dynamics><damping>0.1</damping></dynamics>
            <limit><effort>0</effort></limit>
        </axis>
    </joint>

    <link name="box_0_m1_1">
      <pose>0.0 -0.025 0.025 0 0 0</pose>
      <inertial>
        <mass>0.03</mass>
        <inertia>
          <ixx>0.0003125</ixx>
          <ixy>0.0</ixy>
          <ixz>0.0</ixz>
          <iyy>0.0003125</iyy>
          <iyz>0.0</iyz>
          <izz>0.0003125</izz>
        </inertia>
      </inertial>
      <collision name="collision">
        <geometry>
          <box>
            <size>0.025 0.025 0.025</size>
          </box>
        </geometry>
      </collision>
      <visual name="black">
        <geometry>
          <box>
            <size>0.025 0.025 0.025</size>
          </box>
        </geometry>
        <material>
          <diffuse>0 0 0 1</diffuse>
        </material>
      </visual>
      <visual name="x">
        <pose>0.0 0 0 0 0 0</pose>
        <geometry>
          <box>
            <size>0.0002 0.02 0.02</size>
          </box>
        </geometry>
        <material>
          <diffuse>0 1 0 1</diffuse>
        </material>
      </visual>
      <visual name="y">
        <pose>0 -0.0125 0 0 0 0</pose>
        <geometry>
          <box>
            <size>0.02 0.0002 0.02</size>
          </box>
        </geometry>
        <material>
          <diffuse>1 0.5 0 1</diffuse>
        </material>
      </visual>
      <visual name="z">
        <pose>0 0 0.0125 0 0 0</pose>
        <geometry>
          <box>
            <size>0.02 0.02 0.0002</size>
          </box>
        </geometry>
        <material>
          <diffuse>1 1 1 1</diffuse>
        </material>
      </visual>
    </link>      
    <joint name="ball_0_m1_1" type="ball">
        <pose>0.0 0.025 -0.025 0 0 0</pose> <!-- in child frame -->
        <parent>center</parent>
        <child>box_0_m1_1</child>
        <axis>
            <dynamics><damping>0.1</damping></dynamics>
            <limit><effort>0</effort></limit>
        </axis>
    </joint>

    <link name="box_0_0_m1">
      <pose>0.0 0.0 -0.025 0 0 0</pose>
      <inertial>
        <mass>0.03</mass>
        <inertia>
          <ixx>0.0003125</ixx>
          <ixy>0.0</ixy>
          <ixz>0.0</ixz>
          <iyy>0.0003125</iyy>
          <iyz>0.0</iyz>
          <izz>0.0003125</izz>
        </inertia>
      </inertial>
      <collision name="collision">
        <geometry>
          <box>
            <size>0.025 0.025 0.025</size>
          </box>
        </geometry>
      </collision>
      <visual name="black">
        <geometry>
          <box>
            <size>0.025 0.025 0.025</size>
          </box>
        </geometry>
        <material>
          <diffuse>0 0 0 1</diffuse>
        </material>
      </visual>
      <visual name="x">
        <pose>0.0 0 0 0 0 0</pose>
        <geometry>
          <box>
            <size>0.0002 0.02 0.02</size>
          </box>
        </geometry>
        <material>
          <diffuse>0 1 0 1</diffuse>
        </material>
      </visual>
      <visual name="y">
        <pose>0 0.0 0 0 0 0</pose>
        <geometry>
          <box>
            <size>0.02 0.0002 0.02</size>
          </box>
        </geometry>
        <material>
          <diffuse>1 0 0 1</diffuse>
        </material>
      </visual>
      <visual name="z">
        <pose>0 0 -0.0125 0 0 0</pose>
        <geometry>
          <box>
            <size>0.02 0.02 0.0002</size>
          </box>
        </geometry>
        <material>
          <diffuse>1 1 0 1</diffuse>
        </material>
      </visual>
    </link>      
    <joint name="ball_0_0_m1" type="ball">
        <pose>0.0 0.0 0.025 0 0 0</pose> <!-- in child frame -->
        <parent>center</parent>
        <child>box_0_0_m1</child>
        <axis>
            <dynamics><damping>0.1</damping></dynamics>
            <limit><effort>0</effort></limit>
        </axis>
    </joint>

    <link name="box_0_0_1">
      <pose>0.0 0.0 0.025 0 0 0</pose>
      <inertial>
        <mass>0.03</mass>
        <inertia>
          <ixx>0.0003125</ixx>
          <ixy>0.0</ixy>
          <ixz>0.0</ixz>
          <iyy>0.0003125</iyy>
          <iyz>0.0</iyz>
          <izz>0.0003125</izz>
        </inertia>
      </inertial>
      <collision name="collision">
        <geometry>
          <box>
            <size>0.025 0.025 0.025</size>
          </box>
        </geometry>
      </collision>
      <visual name="black">
        <geometry>
          <box>
            <size>0.025 0.025 0.025</size>
          </box>
        </geometry>
        <material>
          <diffuse>0 0 0 1</diffuse>
        </material>
      </visual>
      <visual name="x">
        <pose>0.0 0 0 0 0 0</pose>
        <geometry>
          <box>
            <size>0.0002 0.02 0.02</size>
          </box>
        </geometry>
        <material>
          <diffuse>0 1 0 1</diffuse>
        </material>
      </visual>
      <visual name="y">
        <pose>0 0.0 0 0 0 0</pose>
        <geometry>
          <box>
            <size>0.02 0.0002 0.02</size>
          </box>
        </geometry>
        <material>
          <diffuse>1 0 0 1</diffuse>
        </material>
      </visual>
      <visual name="z">
        <pose>0 0 0.0125 0 0 0</pose>
        <geometry>
          <box>
            <size>0.02 0.02 0.0002</size>
          </box>
        </geometry>
        <material>
          <diffuse>1 1 1 1</diffuse>
        </material>
      </visual>
    </link>      
    <joint name="ball_0_0_1" type="ball">
        <pose>0.0 0.0 -0.025 0 0 0</pose> <!-- in child frame -->
        <parent>center</parent>
        <child>box_0_0_1</child>
        <axis>
            <dynamics><damping>0.1</damping></dynamics>
            <limit><effort>0</effort></limit>
        </axis>
    </joint>

    <link name="box_0_1_m1">
      <pose>0.0 0.025 -0.025 0 0 0</pose>
      <inertial>
        <mass>0.03</mass>
        <inertia>
          <ixx>0.0003125</ixx>
          <ixy>0.0</ixy>
          <ixz>0.0</ixz>
          <iyy>0.0003125</iyy>
          <iyz>0.0</iyz>
          <izz>0.0003125</izz>
        </inertia>
      </inertial>
      <collision name="collision">
        <geometry>
          <box>
            <size>0.025 0.025 0.025</size>
          </box>
        </geometry>
      </collision>
      <visual name="black">
        <geometry>
          <box>
            <size>0.025 0.025 0.025</size>
          </box>
        </geometry>
        <material>
          <diffuse>0 0 0 1</diffuse>
        </material>
      </visual>
      <visual name="x">
        <pose>0.0 0 0 0 0 0</pose>
        <geometry>
          <box>
            <size>0.0002 0.02 0.02</size>
          </box>
        </geometry>
        <material>
          <diffuse>0 1 0 1</diffuse>
        </material>
      </visual>
      <visual name="y">
        <pose>0 0.0125 0 0 0 0</pose>
        <geometry>
          <box>
            <size>0.02 0.0002 0.02</size>
          </box>
        </geometry>
        <material>
          <diffuse>1 0 0 1</diffuse>
        </material>
      </visual>
      <visual name="z">
        <pose>0 0 -0.0125 0 0 0</pose>
        <geometry>
          <box>
            <size>0.02 0.02 0.0002</size>
          </box>
        </geometry>
        <material>
          <diffuse>1 1 0 1</diffuse>
        </material>
      </visual>
    </link>      
    <joint name="ball_0_1_m1" type="ball">
        <pose>0.0 -0.025 0.025 0 0 0</pose> <!-- in child frame -->
        <parent>center</parent>
        <child>box_0_1_m1</child>
        <axis>
            <dynamics><damping>0.1</damping></dynamics>
            <limit><effort>0</effort></limit>
        </axis>
    </joint>

    <link name="box_0_1_0">
      <pose>0.0 0.025 0.0 0 0 0</pose>
      <inertial>
        <mass>0.03</mass>
        <inertia>
          <ixx>0.0003125</ixx>
          <ixy>0.0</ixy>
          <ixz>0.0</ixz>
          <iyy>0.0003125</iyy>
          <iyz>0.0</iyz>
          <izz>0.0003125</izz>
        </inertia>
      </inertial>
      <collision name="collision">
        <geometry>
          <box>
            <size>0.025 0.025 0.025</size>
          </box>
        </geometry>
      </collision>
      <visual name="black">
        <geometry>
          <box>
            <size>0.025 0.025 0.025</size>
          </box>
        </geometry>
        <material>
          <diffuse>0 0 0 1</diffuse>
        </material>
      </visual>
      <visual name="x">
        <pose>0.0 0 0 0 0 0</pose>
        <geometry>
          <box>
            <size>0.0002 0.02 0.02</size>
          </box>
        </geometry>
        <material>
          <diffuse>0 1 0 1</diffuse>
        </material>
      </visual>
      <visual name="y">
        <pose>0 0.0125 0 0 0 0</pose>
        <geometry>
          <box>
            <size>0.02 0.0002 0.02</size>
          </box>
        </geometry>
        <material>
          <diffuse>1 0 0 1</diffuse>
        </material>
      </visual>
      <visual name="z">
        <pose>0 0 0.0 0 0 0</pose>
        <geometry>
          <box>
            <size>0.02 0.02 0.0002</size>
          </box>
        </geometry>
        <material>
          <diffuse>1 1 1 1</diffuse>
        </material>
      </visual>
    </link>      
    <joint name="ball_0_1_0" type="ball">
        <pose>0.0 -0.025 0.0 0 0 0</pose> <!-- in child frame -->
        <parent>center</parent>
        <child>box_0_1_0</child>
        <axis>
            <dynamics><damping>0.1</damping></dynamics>
            <limit><effort>0</effort></limit>
        </axis>
    </joint>

    <link name="box_0_1_1">
      <pose>0.0 0.025 0.025 0 0 0</pose>
      <inertial>
        <mass>0.03</mass>
        <inertia>
          <ixx>0.0003125</ixx>
          <ixy>0.0</ixy>
          <ixz>0.0</ixz>
          <iyy>0.0003125</iyy>
          <iyz>0.0</iyz>
          <izz>0.0003125</izz>
        </inertia>
      </inertial>
      <collision name="collision">
        <geometry>
          <box>
            <size>0.025 0.025 0.025</size>
          </box>
        </geometry>
      </collision>
      <visual name="black">
        <geometry>
          <box>
            <size>0.025 0.025 0.025</size>
          </box>
        </geometry>
        <material>
          <diffuse>0 0 0 1</diffuse>
        </material>
      </visual>
      <visual name="x">
        <pose>0.0 0 0 0 0 0</pose>
        <geometry>
          <box>
            <size>0.0002 0.02 0.02</size>
          </box>
        </geometry>
        <material>
          <diffuse>0 1 0 1</diffuse>
        </material>
      </visual>
      <visual name="y">
        <pose>0 0.0125 0 0 0 0</pose>
        <geometry>
          <box>
            <size>0.02 0.0002 0.02</size>
          </box>
        </geometry>
        <material>
          <diffuse>1 0 0 1</diffuse>
        </material>
      </visual>
      <visual name="z">
        <pose>0 0 0.0125 0 0 0</pose>
        <geometry>
          <box>
            <size>0.02 0.02 0.0002</size>
          </box>
        </geometry>
        <material>
          <diffuse>1 1 1 1</diffuse>
        </material>
      </visual>
    </link>      
    <joint name="ball_0_1_1" type="ball">
        <pose>0.0 -0.025 -0.025 0 0 0</pose> <!-- in child frame -->
        <parent>center</parent>
        <child>box_0_1_1</child>
        <axis>
            <dynamics><damping>0.1</damping></dynamics>
            <limit><effort>0</effort></limit>
        </axis>
    </joint>

    <link name="box_1_m1_m1">
      <pose>0.025 -0.025 -0.025 0 0 0</pose>
      <inertial>
        <mass>0.03</mass>
        <inertia>
          <ixx>0.0003125</ixx>
          <ixy>0.0</ixy>
          <ixz>0.0</ixz>
          <iyy>0.0003125</iyy>
          <iyz>0.0</iyz>
          <izz>0.0003125</izz>
        </inertia>
      </inertial>
      <collision name="collision">
        <geometry>
          <box>
            <size>0.025 0.025 0.025</size>
          </box>
        </geometry>
      </collision>
      <visual name="black">
        <geometry>
          <box>
            <size>0.025 0.025 0.025</size>
          </box>
        </geometry>
        <material>
          <diffuse>0 0 0 1</diffuse>
        </material>
      </visual>
      <visual name="x">
        <pose>0.0125 0 0 0 0 0</pose>
        <geometry>
          <box>
            <size>0.0002 0.02 0.02</size>
          </box>
        </geometry>
        <material>
          <diffuse>0 1 0 1</diffuse>
        </material>
      </visual>
      <visual name="y">
        <pose>0 -0.0125 0 0 0 0</pose>
        <geometry>
          <box>
            <size>0.02 0.0002 0.02</size>
          </box>
        </geometry>
        <material>
          <diffuse>1 0.5 0 1</diffuse>
        </material>
      </visual>
      <visual name="z">
        <pose>0 0 -0.0125 0 0 0</pose>
        <geometry>
          <box>
            <size>0.02 0.02 0.0002</size>
          </box>
        </geometry>
        <material>
          <diffuse>1 1 0 1</diffuse>
        </material>
      </visual>
    </link>      
    <joint name="ball_1_m1_m1" type="ball">
        <pose>-0.025 0.025 0.025 0 0 0</pose> <!-- in child frame -->
        <parent>center</parent>
        <child>box_1_m1_m1</child>
        <axis>
            <dynamics><damping>0.1</damping></dynamics>
            <limit><effort>0</effort></limit>
        </axis>
    </joint>

    <link name="box_1_m1_0">
      <pose>0.025 -0.025 0.0 0 0 0</pose>
      <inertial>
        <mass>0.03</mass>
        <inertia>
          <ixx>0.0003125</ixx>
          <ixy>0.0</ixy>
          <ixz>0.0</ixz>
          <iyy>0.0003125</iyy>
          <iyz>0.0</iyz>
          <izz>0.0003125</izz>
        </inertia>
      </inertial>
      <collision name="collision">
        <geometry>
          <box>
            <size>0.025 0.025 0.025</size>
          </box>
        </geometry>
      </collision>
      <visual name="black">
        <geometry>
          <box>
            <size>0.025 0.025 0.025</size>
          </box>
        </geometry>
        <material>
          <diffuse>0 0 0 1</diffuse>
        </material>
      </visual>
      <visual name="x">
        <pose>0.0125 0 0 0 0 0</pose>
        <geometry>
          <box>
            <size>0.0002 0.02 0.02</size>
          </box>
        </geometry>
        <material>
          <diffuse>0 1 0 1</diffuse>
        </material>
      </visual>
      <visual name="y">
        <pose>0 -0.0125 0 0 0 0</pose>
        <geometry>
          <box>
            <size>0.02 0.0002 0.02</size>
          </box>
        </geometry>
        <material>
          <diffuse>1 0.5 0 1</diffuse>
        </material>
      </visual>
      <visual name="z">
        <pose>0 0 0.0 0 0 0</pose>
        <geometry>
          <box>
            <size>0.02 0.02 0.0002</size>
          </box>
        </geometry>
        <material>
          <diffuse>1 1 1 1</diffuse>
        </material>
      </visual>
    </link>      
    <joint name="ball_1_m1_0" type="ball">
        <pose>-0.025 0.025 0.0 0 0 0</pose> <!-- in child frame -->
        <parent>center</parent>
        <child>box_1_m1_0</child>
        <axis>
            <dynamics><damping>0.1</damping></dynamics>
            <limit><effort>0</effort></limit>
        </axis>
    </joint>

    <link name="box_1_m1_1">
      <pose>0.025 -0.025 0.025 0 0 0</pose>
      <inertial>
        <mass>0.03</mass>
        <inertia>
          <ixx>0.0003125</ixx>
          <ixy>0.0</ixy>
          <ixz>0.0</ixz>
          <iyy>0.0003125</iyy>
          <iyz>0.0</iyz>
          <izz>0.0003125</izz>
        </inertia>
      </inertial>
      <collision name="collision">
        <geometry>
          <box>
            <size>0.025 0.025 0.025</size>
          </box>
        </geometry>
      </collision>
      <visual name="black">
        <geometry>
          <box>
            <size>0.025 0.025 0.025</size>
          </box>
        </geometry>
        <material>
          <diffuse>0 0 0 1</diffuse>
        </material>
      </visual>
      <visual name="x">
        <pose>0.0125 0 0 0 0 0</pose>
        <geometry>
          <box>
            <size>0.0002 0.02 0.02</size>
          </box>
        </geometry>
        <material>
          <diffuse>0 1 0 1</diffuse>
        </material>
      </visual>
      <visual name="y">
        <pose>0 -0.0125 0 0 0 0</pose>
        <geometry>
          <box>
            <size>0.02 0.0002 0.02</size>
          </box>
        </geometry>
        <material>
          <diffuse>1 0.5 0 1</diffuse>
        </material>
      </visual>
      <visual name="z">
        <pose>0 0 0.0125 0 0 0</pose>
        <geometry>
          <box>
            <size>0.02 0.02 0.0002</size>
          </box>
        </geometry>
        <material>
          <diffuse>1 1 1 1</diffuse>
        </material>
      </visual>
    </link>      
    <joint name="ball_1_m1_1" type="ball">
        <pose>-0.025 0.025 -0.025 0 0 0</pose> <!-- in child frame -->
        <parent>center</parent>
        <child>box_1_m1_1</child>
        <axis>
            <dynamics><damping>0.1</damping></dynamics>
            <limit><effort>0</effort></limit>
        </axis>
    </joint>

    <link name="box_1_0_m1">
      <pose>0.025 0.0 -0.025 0 0 0</pose>
      <inertial>
        <mass>0.03</mass>
        <inertia>
          <ixx>0.0003125</ixx>
          <ixy>0.0</ixy>
          <ixz>0.0</ixz>
          <iyy>0.0003125</iyy>
          <iyz>0.0</iyz>
          <izz>0.0003125</izz>
        </inertia>
      </inertial>
      <collision name="collision">
        <geometry>
          <box>
            <size>0.025 0.025 0.025</size>
          </box>
        </geometry>
      </collision>
      <visual name="black">
        <geometry>
          <box>
            <size>0.025 0.025 0.025</size>
          </box>
        </geometry>
        <material>
          <diffuse>0 0 0 1</diffuse>
        </material>
      </visual>
      <visual name="x">
        <pose>0.0125 0 0 0 0 0</pose>
        <geometry>
          <box>
            <size>0.0002 0.02 0.02</size>
          </box>
        </geometry>
        <material>
          <diffuse>0 1 0 1</diffuse>
        </material>
      </visual>
      <visual name="y">
        <pose>0 0.0 0 0 0 0</pose>
        <geometry>
          <box>
            <size>0.02 0.0002 0.02</size>
          </box>
        </geometry>
        <material>
          <diffuse>1 0 0 1</diffuse>
        </material>
      </visual>
      <visual name="z">
        <pose>0 0 -0.0125 0 0 0</pose>
        <geometry>
          <box>
            <size>0.02 0.02 0.0002</size>
          </box>
        </geometry>
        <material>
          <diffuse>1 1 0 1</diffuse>
        </material>
      </visual>
    </link>      
    <joint name="ball_1_0_m1" type="ball">
        <pose>-0.025 0.0 0.025 0 0 0</pose> <!-- in child frame -->
        <parent>center</parent>
        <child>box_1_0_m1</child>
        <axis>
            <dynamics><damping>0.1</damping></dynamics>
            <limit><effort>0</effort></limit>
        </axis>
    </joint>

    <link name="box_1_0_0">
      <pose>0.025 0.0 0.0 0 0 0</pose>
      <inertial>
        <mass>0.03</mass>
        <inertia>
          <ixx>0.0003125</ixx>
          <ixy>0.0</ixy>
          <ixz>0.0</ixz>
          <iyy>0.0003125</iyy>
          <iyz>0.0</iyz>
          <izz>0.0003125</izz>
        </inertia>
      </inertial>
      <collision name="collision">
        <geometry>
          <box>
            <size>0.025 0.025 0.025</size>
          </box>
        </geometry>
      </collision>
      <visual name="black">
        <geometry>
          <box>
            <size>0.025 0.025 0.025</size>
          </box>
        </geometry>
        <material>
          <diffuse>0 0 0 1</diffuse>
        </material>
      </visual>
      <visual name="x">
        <pose>0.0125 0 0 0 0 0</pose>
        <geometry>
          <box>
            <size>0.0002 0.02 0.02</size>
          </box>
        </geometry>
        <material>
          <diffuse>0 1 0 1</diffuse>
        </material>
      </visual>
      <visual name="y">
        <pose>0 0.0 0 0 0 0</pose>
        <geometry>
          <box>
            <size>0.02 0.0002 0.02</size>
          </box>
        </geometry>
        <material>
          <diffuse>1 0 0 1</diffuse>
        </material>
      </visual>
      <visual name="z">
        <pose>0 0 0.0 0 0 0</pose>
        <geometry>
          <box>
            <size>0.02 0.02 0.0002</size>
          </box>
        </geometry>
        <material>
          <diffuse>1 1 1 1</diffuse>
        </material>
      </visual>
    </link>      
    <joint name="ball_1_0_0" type="ball">
        <pose>-0.025 0.0 0.0 0 0 0</pose> <!-- in child frame -->
        <parent>center</parent>
        <child>box_1_0_0</child>
        <axis>
            <dynamics><damping>0.1</damping></dynamics>
            <limit><effort>0</effort></limit>
        </axis>
    </joint>

    <link name="box_1_0_1">
      <pose>0.025 0.0 0.025 0 0 0</pose>
      <inertial>
        <mass>0.03</mass>
        <inertia>
          <ixx>0.0003125</ixx>
          <ixy>0.0</ixy>
          <ixz>0.0</ixz>
          <iyy>0.0003125</iyy>
          <iyz>0.0</iyz>
          <izz>0.0003125</izz>
        </inertia>
      </inertial>
      <collision name="collision">
        <geometry>
          <box>
            <size>0.025 0.025 0.025</size>
          </box>
        </geometry>
      </collision>
      <visual name="black">
        <geometry>
          <box>
            <size>0.025 0.025 0.025</size>
          </box>
        </geometry>
        <material>
          <diffuse>0 0 0 1</diffuse>
        </material>
      </visual>
      <visual name="x">
        <pose>0.0125 0 0 0 0 0</pose>
        <geometry>
          <box>
            <size>0.0002 0.02 0.02</size>
          </box>
        </geometry>
        <material>
          <diffuse>0 1 0 1</diffuse>
        </material>
      </visual>
      <visual name="y">
        <pose>0 0.0 0 0 0 0</pose>
        <geometry>
          <box>
            <size>0.02 0.0002 0.02</size>
          </box>
        </geometry>
        <material>
          <diffuse>1 0 0 1</diffuse>
        </material>
      </visual>
      <visual name="z">
        <pose>0 0 0.0125 0 0 0</pose>
        <geometry>
          <box>
            <size>0.02 0.02 0.0002</size>
          </box>
        </geometry>
        <material>
          <diffuse>1 1 1 1</diffuse>
        </material>
      </visual>
    </link>      
    <joint name="ball_1_0_1" type="ball">
        <pose>-0.025 0.0 -0.025 0 0 0</pose> <!-- in child frame -->
        <parent>center</parent>
        <child>box_1_0_1</child>
        <axis>
            <dynamics><damping>0.1</damping></dynamics>
            <limit><effort>0</effort></limit>
        </axis>
    </joint>

    <link name="box_1_1_m1">
      <pose>0.025 0.025 -0.025 0 0 0</pose>
      <inertial>
        <mass>0.03</mass>
        <inertia>
          <ixx>0.0003125</ixx>
          <ixy>0.0</ixy>
          <ixz>0.0</ixz>
          <iyy>0.0003125</iyy>
          <iyz>0.0</iyz>
          <izz>0.0003125</izz>
        </inertia>
      </inertial>
      <collision name="collision">
        <geometry>
          <box>
            <size>0.025 0.025 0.025</size>
          </box>
        </geometry>
      </collision>
      <visual name="black">
        <geometry>
          <box>
            <size>0.025 0.025 0.025</size>
          </box>
        </geometry>
        <material>
          <diffuse>0 0 0 1</diffuse>
        </material>
      </visual>
      <visual name="x">
        <pose>0.0125 0 0 0 0 0</pose>
        <geometry>
          <box>
            <size>0.0002 0.02 0.02</size>
          </box>
        </geometry>
        <material>
          <diffuse>0 1 0 1</diffuse>
        </material>
      </visual>
      <visual name="y">
        <pose>0 0.0125 0 0 0 0</pose>
        <geometry>
          <box>
            <size>0.02 0.0002 0.02</size>
          </box>
        </geometry>
        <material>
          <diffuse>1 0 0 1</diffuse>
        </material>
      </visual>
      <visual name="z">
        <pose>0 0 -0.0125 0 0 0</pose>
        <geometry>
          <box>
            <size>0.02 0.02 0.0002</size>
          </box>
        </geometry>
        <material>
          <diffuse>1 1 0 1</diffuse>
        </material>
      </visual>
    </link>      
    <joint name="ball_1_1_m1" type="ball">
        <pose>-0.025 -0.025 0.025 0 0 0</pose> <!-- in child frame -->
        <parent>center</parent>
        <child>box_1_1_m1</child>
        <axis>
            <dynamics><damping>0.1</damping></dynamics>
            <limit><effort>0</effort></limit>
        </axis>
    </joint>

    <link name="box_1_1_0">
      <pose>0.025 0.025 0.0 0 0 0</pose>
      <inertial>
        <mass>0.03</mass>
        <inertia>
          <ixx>0.0003125</ixx>
          <ixy>0.0</ixy>
          <ixz>0.0</ixz>
          <iyy>0.0003125</iyy>
          <iyz>0.0</iyz>
          <izz>0.0003125</izz>
        </inertia>
      </inertial>
      <collision name="collision">
        <geometry>
          <box>
            <size>0.025 0.025 0.025</size>
          </box>
        </geometry>
      </collision>
      <visual name="black">
        <geometry>
          <box>
            <size>0.025 0.025 0.025</size>
          </box>
        </geometry>
        <material>
          <diffuse>0 0 0 1</diffuse>
        </material>
      </visual>
      <visual name="x">
        <pose>0.0125 0 0 0 0 0</pose>
        <geometry>
          <box>
            <size>0.0002 0.02 0.02</size>
          </box>
        </geometry>
        <material>
          <diffuse>0 1 0 1</diffuse>
        </material>
      </visual>
      <visual name="y">
        <pose>0 0.0125 0 0 0 0</pose>
        <geometry>
          <box>
            <size>0.02 0.0002 0.02</size>
          </box>
        </geometry>
        <material>
          <diffuse>1 0 0 1</diffuse>
        </material>
      </visual>
      <visual name="z">
        <pose>0 0 0.0 0 0 0</pose>
        <geometry>
          <box>
            <size>0.02 0.02 0.0002</size>
          </box>
        </geometry>
        <material>
          <diffuse>1 1 1 1</diffuse>
        </material>
      </visual>
    </link>      
    <joint name="ball_1_1_0" type="ball">
        <pose>-0.025 -0.025 0.0 0 0 0</pose> <!-- in child frame -->
        <parent>center</parent>
        <child>box_1_1_0</child>
        <axis>
            <dynamics><damping>0.1</damping></dynamics>
            <limit><effort>0</effort></limit>
        </axis>
    </joint>

    <link name="box_1_1_1">
      <pose>0.025 0.025 0.025 0 0 0</pose>
      <inertial>
        <mass>0.03</mass>
        <inertia>
          <ixx>0.0003125</ixx>
          <ixy>0.0</ixy>
          <ixz>0.0</ixz>
          <iyy>0.0003125</iyy>
          <iyz>0.0</iyz>
          <izz>0.0003125</izz>
        </inertia>
      </inertial>
      <collision name="collision">
        <geometry>
          <box>
            <size>0.025 0.025 0.025</size>
          </box>
        </geometry>
      </collision>
      <visual name="black">
        <geometry>
          <box>
            <size>0.025 0.025 0.025</size>
          </box>
        </geometry>
        <material>
          <diffuse>0 0 0 1</diffuse>
        </material>
      </visual>
      <visual name="x">
        <pose>0.0125 0 0 0 0 0</pose>
        <geometry>
          <box>
            <size>0.0002 0.02 0.02</size>
          </box>
        </geometry>
        <material>
          <diffuse>0 1 0 1</diffuse>
        </material>
      </visual>
      <visual name="y">
        <pose>0 0.0125 0 0 0 0</pose>
        <geometry>
          <box>
            <size>0.02 0.0002 0.02</size>
          </box>
        </geometry>
        <material>
          <diffuse>1 0 0 1</diffuse>
        </material>
      </visual>
      <visual name="z">
        <pose>0 0 0.0125 0 0 0</pose>
        <geometry>
          <box>
            <size>0.02 0.02 0.0002</size>
          </box>
        </geometry>
        <material>
          <diffuse>1 1 1 1</diffuse>
        </material>
      </visual>
    </link>      
    <joint name="ball_1_1_1" type="ball">
        <pose>-0.025 -0.025 -0.025 0 0 0</pose> <!-- in child frame -->
        <parent>center</parent>
        <child>box_1_1_1</child>
        <axis>
            <dynamics><damping>0.1</damping></dynamics>
            <limit><effort>0</effort></limit>
        </axis>
    </joint>

  </model>
</sdf>
