<?xml version="1.0"?>

<!-- This was inspired by the model in
https://github.com/TeaganLi/RubikCube-InHandManipulation; I've
re-implemented from scratch a much simpler version here.

The essential mechanism is that each cube is attached to the toy center by a
ball joint. The rest is handled by contact forces between the boxes. I've just
taken box collision geometry for everything; it seems to work well enough.

Each cube is 0.03kg for each 2.5cm cube , but also scaled the inertia
by 100 for improved numerics. -->

<sdf version="1.7">
  <model name="rubiks_cube">
    <link name="center"/>
    <link name="box_0_0_0">
      <pose>-0.0125 -0.0125 -0.0125 0 0 0</pose>
      <inertial>
        <mass>0.03</mass>
        <inertia>
          <ixx>0.0003125</ixx>
          <ixy>0.0</ixy>
          <ixz>0.0</ixz>
          <iyy>0.0003125</iyy>
          <iyz>0.0</iyz>
          <izz>0.0003125</izz>
        </inertia>
      </inertial>
      <collision name="collision">
        <geometry>
          <box>
            <size>0.025 0.025 0.025</size>
          </box>
        </geometry>
      </collision>
      <visual name="black">
        <geometry>
          <box>
            <size>0.025 0.025 0.025</size>
          </box>
        </geometry>
        <material>
          <diffuse>0 0 0 1</diffuse>
        </material>
      </visual>
      <visual name="blue">
        <pose>-0.0125 0 0 0 0 0</pose>
        <geometry>
          <box>
            <size>0.0002 0.02 0.02</size>
          </box>
        </geometry>
        <material>
          <diffuse>0 0 1 1</diffuse>
        </material>
      </visual>
      <visual name="orange">
        <pose>0 -0.0125 0 0 0 0</pose>
        <geometry>
          <box>
            <size>0.02 0.0002 0.02</size>
          </box>
        </geometry>
        <material>
          <diffuse>1 0.5 0 1</diffuse>
        </material>
      </visual>
      <visual name="yellow">
        <pose>0 0 -0.0125 0 0 0</pose>
        <geometry>
          <box>
            <size>0.02 0.02 0.0002</size>
          </box>
        </geometry>
        <material>
          <diffuse>1 1 0 1</diffuse>
        </material>
      </visual>
    </link>      
    <joint name="ball_0_0_0" type="ball">
        <pose>0.0125 0.0125 0.0125 0 0 0</pose> <!-- in child frame -->
        <parent>center</parent>
        <child>box_0_0_0</child>
        <axis>
            <dynamics><damping>0.1</damping></dynamics>
            <limit><effort>0</effort></limit>
        </axis>
    </joint>
    <link name="box_1_0_0">
      <pose>0.0125 -0.0125 -0.0125 0 0 0</pose>
      <inertial>
        <mass>0.03</mass>
        <inertia>
          <ixx>0.0003125</ixx>
          <ixy>0.0</ixy>
          <ixz>0.0</ixz>
          <iyy>0.0003125</iyy>
          <iyz>0.0</iyz>
          <izz>0.0003125</izz>
        </inertia>
      </inertial>
      <collision name="collision">
        <geometry>
          <box>
            <size>0.025 0.025 0.025</size>
          </box>
        </geometry>
      </collision>
      <visual name="black">
        <geometry>
          <box>
            <size>0.025 0.025 0.025</size>
          </box>
        </geometry>
        <material>
          <diffuse>0 0 0 1</diffuse>
        </material>
      </visual>
      <visual name="green">
        <pose>0.0125 0 0 0 0 0</pose>
        <geometry>
          <box>
            <size>0.0002 0.02 0.02</size>
          </box>
        </geometry>
        <material>
          <diffuse>0 1 0 1</diffuse>
        </material>
      </visual>
      <visual name="orange">
        <pose>0 -0.0125 0 0 0 0</pose>
        <geometry>
          <box>
            <size>0.02 0.0002 0.02</size>
          </box>
        </geometry>
        <material>
          <diffuse>1 0.5 0 1</diffuse>
        </material>
      </visual>
      <visual name="yellow">
        <pose>0 0 -0.0125 0 0 0</pose>
        <geometry>
          <box>
            <size>0.02 0.02 0.0002</size>
          </box>
        </geometry>
        <material>
          <diffuse>1 1 0 1</diffuse>
        </material>
      </visual>
    </link>
    <joint name="ball_1_0_0" type="ball">
        <pose>-0.0125 0.0125 0.0125 0 0 0</pose> <!-- in child frame -->
        <parent>center</parent>
        <child>box_1_0_0</child>
        <axis>
            <dynamics><damping>0.1</damping></dynamics>
            <limit><effort>0</effort></limit>
        </axis>
    </joint>
    <link name="box_0_1_0">
      <pose>-0.0125 0.0125 -0.0125 0 0 0</pose>
      <inertial>
        <mass>0.03</mass>
        <inertia>
          <ixx>0.0003125</ixx>
          <ixy>0.0</ixy>
          <ixz>0.0</ixz>
          <iyy>0.0003125</iyy>
          <iyz>0.0</iyz>
          <izz>0.0003125</izz>
        </inertia>
      </inertial>
      <collision name="collision">
        <geometry>
          <box>
            <size>0.025 0.025 0.025</size>
          </box>
        </geometry>
      </collision>
      <visual name="black">
        <geometry>
          <box>
            <size>0.025 0.025 0.025</size>
          </box>
        </geometry>
        <material>
          <diffuse>0 0 0 1</diffuse>
        </material>
      </visual>
      <visual name="blue">
        <pose>-0.0125 0 0 0 0 0</pose>
        <geometry>
          <box>
            <size>0.0002 0.02 0.02</size>
          </box>
        </geometry>
        <material>
          <diffuse>0 0 1 1</diffuse>
        </material>
      </visual>
      <visual name="red">
        <pose>0 0.0125 0 0 0 0</pose>
        <geometry>
          <box>
            <size>0.02 0.0002 0.02</size>
          </box>
        </geometry>
        <material>
          <diffuse>1 0 0 1</diffuse>
        </material>
      </visual>
      <visual name="yellow">
        <pose>0 0 -0.0125 0 0 0</pose>
        <geometry>
          <box>
            <size>0.02 0.02 0.0002</size>
          </box>
        </geometry>
        <material>
          <diffuse>1 1 0 1</diffuse>
        </material>
      </visual>
    </link>      
    <joint name="ball_0_1_0" type="ball">
        <pose>0.0125 -0.0125 0.0125 0 0 0</pose> <!-- in child frame -->
        <parent>center</parent>
        <child>box_0_1_0</child>
        <axis>
            <dynamics><damping>0.1</damping></dynamics>
            <limit><effort>0</effort></limit>
        </axis>
    </joint>
    <link name="box_1_1_0">
      <pose>0.0125 0.0125 -0.0125 0 0 0</pose>
      <inertial>
        <mass>0.03</mass>
        <inertia>
          <ixx>0.0003125</ixx>
          <ixy>0.0</ixy>
          <ixz>0.0</ixz>
          <iyy>0.0003125</iyy>
          <iyz>0.0</iyz>
          <izz>0.0003125</izz>
        </inertia>
      </inertial>
      <collision name="collision">
        <geometry>
          <box>
            <size>0.025 0.025 0.025</size>
          </box>
        </geometry>
      </collision>
      <visual name="black">
        <geometry>
          <box>
            <size>0.025 0.025 0.025</size>
          </box>
        </geometry>
        <material>
          <diffuse>0 0 0 1</diffuse>
        </material>
      </visual>
      <visual name="green">
        <pose>0.0125 0 0 0 0 0</pose>
        <geometry>
          <box>
            <size>0.0002 0.02 0.02</size>
          </box>
        </geometry>
        <material>
          <diffuse>0 1 0 1</diffuse>
        </material>
      </visual>
      <visual name="red">
        <pose>0 0.0125 0 0 0 0</pose>
        <geometry>
          <box>
            <size>0.02 0.0002 0.02</size>
          </box>
        </geometry>
        <material>
          <diffuse>1 0 0 1</diffuse>
        </material>
      </visual>
      <visual name="yellow">
        <pose>0 0 -0.0125 0 0 0</pose>
        <geometry>
          <box>
            <size>0.02 0.02 0.0002</size>
          </box>
        </geometry>
        <material>
          <diffuse>1 1 0 1</diffuse>
        </material>
      </visual>
    </link>      
    <joint name="ball_1_1_0" type="ball">
        <pose>-0.0125 -0.0125 0.0125 0 0 0</pose> <!-- in child frame -->
        <parent>center</parent>
        <child>box_1_1_0</child>
        <axis>
            <dynamics><damping>0.1</damping></dynamics>
            <limit><effort>0</effort></limit>
        </axis>
    </joint>
    <link name="box_0_0_1">
      <pose>-0.0125 -0.0125 0.0125 0 0 0</pose>
      <inertial>
        <mass>0.03</mass>
        <inertia>
          <ixx>0.0003125</ixx>
          <ixy>0.0</ixy>
          <ixz>0.0</ixz>
          <iyy>0.0003125</iyy>
          <iyz>0.0</iyz>
          <izz>0.0003125</izz>
        </inertia>
      </inertial>
      <collision name="collision">
        <geometry>
          <box>
            <size>0.025 0.025 0.025</size>
          </box>
        </geometry>
      </collision>
      <visual name="black">
        <geometry>
          <box>
            <size>0.025 0.025 0.025</size>
          </box>
        </geometry>
        <material>
          <diffuse>0 0 0 1</diffuse>
        </material>
      </visual>
      <visual name="blue">
        <pose>-0.0125 0 0 0 0 0</pose>
        <geometry>
          <box>
            <size>0.0002 0.02 0.02</size>
          </box>
        </geometry>
        <material>
          <diffuse>0 0 1 1</diffuse>
        </material>
      </visual>
      <visual name="orange">
        <pose>0 -0.0125 0 0 0 0</pose>
        <geometry>
          <box>
            <size>0.02 0.0002 0.02</size>
          </box>
        </geometry>
        <material>
          <diffuse>1 0.5 0 1</diffuse>
        </material>
      </visual>
      <visual name="white">
        <pose>0 0 0.0125 0 0 0</pose>
        <geometry>
          <box>
            <size>0.02 0.02 0.0002</size>
          </box>
        </geometry>
        <material>
          <diffuse>1 1 1 1</diffuse>
        </material>
      </visual>
    </link>      
    <joint name="ball_0_0_1" type="ball">
        <pose>0.0125 0.0125 -0.0125 0 0 0</pose> <!-- in child frame -->
        <parent>center</parent>
        <child>box_0_0_1</child>
        <axis>
            <dynamics><damping>0.1</damping></dynamics>
            <limit><effort>0</effort></limit>
        </axis>
    </joint>
    <link name="box_1_0_1">
      <pose>0.0125 -0.0125 0.0125 0 0 0</pose>
      <inertial>
        <mass>0.03</mass>
        <inertia>
          <ixx>0.0003125</ixx>
          <ixy>0.0</ixy>
          <ixz>0.0</ixz>
          <iyy>0.0003125</iyy>
          <iyz>0.0</iyz>
          <izz>0.0003125</izz>
        </inertia>
      </inertial>
      <collision name="collision">
        <geometry>
          <box>
            <size>0.025 0.025 0.025</size>
          </box>
        </geometry>
      </collision>
      <visual name="black">
        <geometry>
          <box>
            <size>0.025 0.025 0.025</size>
          </box>
        </geometry>
        <material>
          <diffuse>0 0 0 1</diffuse>
        </material>
      </visual>
      <visual name="green">
        <pose>0.0125 0 0 0 0 0</pose>
        <geometry>
          <box>
            <size>0.0002 0.02 0.02</size>
          </box>
        </geometry>
        <material>
          <diffuse>0 1 0 1</diffuse>
        </material>
      </visual>
      <visual name="orange">
        <pose>0 -0.0125 0 0 0 0</pose>
        <geometry>
          <box>
            <size>0.02 0.0002 0.02</size>
          </box>
        </geometry>
        <material>
          <diffuse>1 0.5 0 1</diffuse>
        </material>
      </visual>
      <visual name="white">
        <pose>0 0 0.0125 0 0 0</pose>
        <geometry>
          <box>
            <size>0.02 0.02 0.0002</size>
          </box>
        </geometry>
        <material>
          <diffuse>1 1 1 1</diffuse>
        </material>
      </visual>
    </link>
    <joint name="ball_1_0_1" type="ball">
        <pose>-0.0125 0.0125 -0.0125 0 0 0</pose> <!-- in child frame -->
        <parent>center</parent>
        <child>box_1_0_1</child>
        <axis>
            <dynamics><damping>0.1</damping></dynamics>
            <limit><effort>0</effort></limit>
        </axis>
    </joint>
    <link name="box_0_1_1">
      <pose>-0.0125 0.0125 0.0125 0 0 0</pose>
      <inertial>
        <mass>0.03</mass>
        <inertia>
          <ixx>0.0003125</ixx>
          <ixy>0.0</ixy>
          <ixz>0.0</ixz>
          <iyy>0.0003125</iyy>
          <iyz>0.0</iyz>
          <izz>0.0003125</izz>
        </inertia>
      </inertial>
      <collision name="collision">
        <geometry>
          <box>
            <size>0.025 0.025 0.025</size>
          </box>
        </geometry>
      </collision>
      <visual name="black">
        <geometry>
          <box>
            <size>0.025 0.025 0.025</size>
          </box>
        </geometry>
        <material>
          <diffuse>0 0 0 1</diffuse>
        </material>
      </visual>
      <visual name="blue">
        <pose>-0.0125 0 0 0 0 0</pose>
        <geometry>
          <box>
            <size>0.0002 0.02 0.02</size>
          </box>
        </geometry>
        <material>
          <diffuse>0 0 1 1</diffuse>
        </material>
      </visual>
      <visual name="red">
        <pose>0 0.0125 0 0 0 0</pose>
        <geometry>
          <box>
            <size>0.02 0.0002 0.02</size>
          </box>
        </geometry>
        <material>
          <diffuse>1 0 0 1</diffuse>
        </material>
      </visual>
      <visual name="white">
        <pose>0 0 0.0125 0 0 0</pose>
        <geometry>
          <box>
            <size>0.02 0.02 0.0002</size>
          </box>
        </geometry>
        <material>
          <diffuse>1 1 1 1</diffuse>
        </material>
      </visual>
    </link>      
    <joint name="ball_0_1_1" type="ball">
        <pose>0.0125 -0.0125 -0.0125 0 0 0</pose> <!-- in child frame -->
        <parent>center</parent>
        <child>box_0_1_1</child>
        <axis>
            <dynamics><damping>0.1</damping></dynamics>
            <limit><effort>0</effort></limit>
        </axis>
    </joint>
    <link name="box_1_1_1">
      <pose>0.0125 0.0125 0.0125 0 0 0</pose>
      <inertial>
        <mass>0.03</mass>
        <inertia>
          <ixx>0.0003125</ixx>
          <ixy>0.0</ixy>
          <ixz>0.0</ixz>
          <iyy>0.0003125</iyy>
          <iyz>0.0</iyz>
          <izz>0.0003125</izz>
        </inertia>
      </inertial>
      <collision name="collision">
        <geometry>
          <box>
            <size>0.025 0.025 0.025</size>
          </box>
        </geometry>
      </collision>
      <visual name="black">
        <geometry>
          <box>
            <size>0.025 0.025 0.025</size>
          </box>
        </geometry>
        <material>
          <diffuse>0 0 0 1</diffuse>
        </material>
      </visual>
      <visual name="green">
        <pose>0.0125 0 0 0 0 0</pose>
        <geometry>
          <box>
            <size>0.0002 0.02 0.02</size>
          </box>
        </geometry>
        <material>
          <diffuse>0 1 0 1</diffuse>
        </material>
      </visual>
      <visual name="red">
        <pose>0 0.0125 0 0 0 0</pose>
        <geometry>
          <box>
            <size>0.02 0.0002 0.02</size>
          </box>
        </geometry>
        <material>
          <diffuse>1 0 0 1</diffuse>
        </material>
      </visual>
      <visual name="white">
        <pose>0 0 0.0125 0 0 0</pose>
        <geometry>
          <box>
            <size>0.02 0.02 0.0002</size>
          </box>
        </geometry>
        <material>
          <diffuse>1 1 1 1</diffuse>
        </material>
      </visual>
    </link>      
    <joint name="ball_1_1_1" type="ball">
        <pose>-0.0125 -0.0125 -0.0125 0 0 0</pose> <!-- in child frame -->
        <parent>center</parent>
        <child>box_1_1_1</child>
        <axis>
            <dynamics><damping>0.1</damping></dynamics>
            <limit><effort>0</effort></limit>
        </axis>
    </joint>
  </model>
</sdf>